<?xml version="1.0"?>
<!-- This URDF was automatically created by SolidWorks to URDF Exporter! Originally created by
Stephen Brawner (brawner@gmail.com) 
     Commit Version: 1.6.0-1-g15f4949  Build Version: 1.6.7594.29634
     For more information, please see http://wiki.ros.org/sw_urdf_exporter -->
<robot xmlns:xacro="http://www.ros.org/wiki/xacro" name="kuka_kr210_r2700">
  <material name="Blue">
    <color rgba="0 0 1 1" />
  </material>

  <xacro:property name="tool0_length" value="1.9" />
  <xacro:property name="tool0_width" value="0.853" />
  <!-- <xacro:property name="tool0_height" value="0.30876" /> -->
  <xacro:property name="tool0_height" value="0.3" />
  <xacro:property name="spring" value="0.05" />

  <xacro:macro name="kuka_kr210_r2700_cover">
    <link
      name="base_arm">
      <inertial>
        <origin
          xyz="-0.11721 0.00093362 0.10365"
          rpy="0 0 0" />
        <mass
          value="553.48" />
        <inertia
          ixx="12.503"
          ixy="0.066841"
          ixz="2.8363"
          iyy="27.301"
          iyz="-0.016485"
          izz="33.309" />
      </inertial>
      <visual>
        <origin
          xyz="0 0 0"
          rpy="0 0 0" />
        <geometry>
          <mesh
            filename="package://lt_description/meshes/kr210r2700_cover/base_arm.STL" />
        </geometry>
        <material
          name="">
          <color
            rgba="0.75294 0.75294 0.75294 1" />
        </material>
      </visual>
      <collision>
        <origin
          xyz="0 0 0"
          rpy="0 0 0" />
        <geometry>
          <mesh
            filename="package://lt_description/meshes/kr210r2700_cover/base_arm.STL" />
        </geometry>
      </collision>
    </link>
    <link
      name="link_1">
      <inertial>
        <origin
          xyz="-0.011212 0.01436 0.24467"
          rpy="0 0 0" />
        <mass
          value="0.01" />
        <inertia
          ixx="17.857"
          ixy="-2.6899"
          ixz="1.6654"
          iyy="33.002"
          iyz="-0.49207"
          izz="29.842" />
      </inertial>
      <visual>
        <origin
          xyz="0 0 0"
          rpy="0 0 0" />
        <geometry>
          <mesh
            filename="package://lt_description/meshes/kr210r2700_cover/link_1.STL" />
        </geometry>
        <material
          name="">
          <color
            rgba="0.75294 0.75294 0.75294 1" />
        </material>
      </visual>
      <collision>
        <origin
          xyz="0 0 0"
          rpy="0 0 0" />
        <geometry>
          <mesh
            filename="package://lt_description/meshes/kr210r2700_cover/link_1.STL" />
        </geometry>
      </collision>
    </link>
    <joint
      name="joint_a1"
      type="revolute">
      <origin
        xyz="0 0 0.2236"
        rpy="0 0 0" />
      <parent
        link="base_arm" />
      <child
        link="link_1" />
      <axis
        xyz="0 0 -1" />
      <limit
        lower="${radians(-184.5)}"
        upper="${radians(185)}"
        effort="100"
        velocity="1" />
    </joint>
    <link
      name="link_2">
      <inertial>
        <origin
          xyz="0.44927 0.00098297 -0.2316"
          rpy="0 0 0" />
        <mass
          value="0.01" />
        <inertia
          ixx="11.762"
          ixy="0.38402"
          ixz="9.1746"
          iyy="137.26"
          iyz="-0.011243"
          izz="135.8" />
      </inertial>
      <visual>
        <origin
          xyz="0 0 0"
          rpy="0 0 0" />
        <geometry>
          <mesh
            filename="package://lt_description/meshes/kr210r2700_cover/link_2.STL" />
        </geometry>
        <material
          name="">
          <color
            rgba="0.75294 0.75294 0.75294 1" />
        </material>
      </visual>
      <collision>
        <origin
          xyz="0 0 0"
          rpy="0 0 0" />
        <geometry>
          <mesh
            filename="package://lt_description/meshes/kr210r2700_cover/link_2.STL" />
        </geometry>
      </collision>
    </link>
    <joint
      name="joint_a2"
      type="revolute">
      <origin
        xyz="0.33 0.009 0.4094"
        rpy="-1.5708 0 0" />
      <parent
        link="link_1" />
      <child
        link="link_2" />
      <axis
        xyz="0 0 1" />
      <limit
        lower="${radians(-140)}"
        upper="${radians(-4.94)}"
        effort="100"
        velocity="1" />
    </joint>
    <link
      name="link_3">
      <inertial>
        <origin
          xyz="0.26439 -0.10607 0.10511"
          rpy="0 0 0" />
        <mass
          value="0.01" />
        <inertia
          ixx="3.9646"
          ixy="0.046601"
          ixz="-0.78788"
          iyy="31.952"
          iyz="0.20533"
          izz="31.684" />
      </inertial>
      <visual>
        <origin
          xyz="0 0 0"
          rpy="0 0 0" />
        <geometry>
          <mesh
            filename="package://lt_description/meshes/kr210r2700_cover/link_3.STL" />
        </geometry>
        <material
          name="">
          <color
            rgba="0.75294 0.75294 0.75294 1" />
        </material>
      </visual>
      <collision>
        <origin
          xyz="0 0 0"
          rpy="0 0 0" />
        <geometry>
          <mesh
            filename="package://lt_description/meshes/kr210r2700_cover/link_3.STL" />
        </geometry>
      </collision>
    </link>
    <joint
      name="joint_a3"
      type="revolute">
      <origin
        xyz="1.15 0 -0.114"
        rpy="0 0 -1.57079" />
      <parent
        link="link_2" />
      <child
        link="link_3" />
      <axis
        xyz="0 0 1" />
      <limit
        lower="${radians(-48)}"
        upper="${radians(168)}"
        effort="100"
        velocity="1" />
    </joint>
    <link
      name="link_4">
      <inertial>
        <origin
          xyz="-5.2916E-06 -0.0044928 0.18467"
          rpy="0 0 0" />
        <mass
          value="0.01" />
        <inertia
          ixx="0.69268"
          ixy="7.2733E-06"
          ixz="-1.9285E-05"
          iyy="0.6955"
          iyz="0.031592"
          izz="0.097091" />
      </inertial>
      <visual>
        <origin
          xyz="0 0 0"
          rpy="0 0 0" />
        <geometry>
          <mesh
            filename="package://lt_description/meshes/kr210r2700_cover/link_4.STL" />
        </geometry>
        <material
          name="">
          <color
            rgba="0.75294 0.75294 0.75294 1" />
        </material>
      </visual>
      <collision>
        <origin
          xyz="0 0 0"
          rpy="0 0 0" />
        <geometry>
          <mesh
            filename="package://lt_description/meshes/kr210r2700_cover/link_4.STL" />
        </geometry>
      </collision>
    </link>
    <joint
      name="joint_a4"
      type="revolute">
      <origin
        xyz="0.115 0.8685 0.105"
        rpy="-1.5708 0 0" />
      <parent
        link="link_3" />
      <child
        link="link_4" />
      <axis
        xyz="0 0 -1" />
      <limit
        lower="${radians(-300)}"
        upper="${radians(350)}"
        effort="100"
        velocity="1" />
    </joint>
    <link
      name="link_5">
      <inertial>
        <origin
          xyz="-4.5381E-05 0.051765 -0.025172"
          rpy="0 0 0" />
        <mass
          value="0.01" />
        <inertia
          ixx="0.66981"
          ixy="0.00015038"
          ixz="0.00027093"
          iyy="0.4771"
          iyz="0.11692"
          izz="0.42151" />
      </inertial>
      <visual>
        <origin
          xyz="0 0 0"
          rpy="0 0 0" />
        <geometry>
          <mesh
            filename="package://lt_description/meshes/kr210r2700_cover/link_5.STL" />
        </geometry>
        <material
          name="">
          <color
            rgba="0.75294 0.75294 0.75294 1" />
        </material>
      </visual>
      <collision>
        <origin
          xyz="0 0 0"
          rpy="0 0 0" />
        <geometry>
          <mesh
            filename="package://lt_description/meshes/kr210r2700_cover/link_5.STL" />
        </geometry>
      </collision>
    </link>
    <joint
      name="joint_a5"
      type="revolute">
      <origin
        xyz="0 -0.059 0.3515"
        rpy="1.5708 0 0" />
      <parent
        link="link_4" />
      <child
        link="link_5" />
      <axis
        xyz="0 0 1" />
      <limit
        lower="${radians(-90)}"
        upper="${radians(110)}"
        effort="100"
        velocity="1" />
    </joint>
    <link
      name="link_6">
      <inertial>
        <origin
          xyz="2.1759E-05 -4.6365E-05 0.023222"
          rpy="0 0 0" />
        <mass
          value="0.01" />
        <inertia
          ixx="0.0059812"
          ixy="4.6968E-06"
          ixz="-1.062E-06"
          iyy="0.0059674"
          iyz="1.7586E-06"
          izz="0.010749" />
      </inertial>
      <visual>
        <origin
          xyz="0 0 0"
          rpy="0 0 0" />
        <geometry>
          <mesh
            filename="package://lt_description/meshes/kr210r2700_cover/link_6.STL" />
        </geometry>
        <material
          name="">
          <color
            rgba="0.75294 0.75294 0.75294 1" />
        </material>
      </visual>
      <collision>
        <origin
          xyz="0 0 0"
          rpy="0 0 0" />
        <geometry>
          <mesh
            filename="package://lt_description/meshes/kr210r2700_cover/link_6.STL" />
        </geometry>
      </collision>
    </link>
    <joint
      name="joint_a6"
      type="revolute">
      <origin
        xyz="0 0.17 -0.059"
        rpy="-1.5708 0 0" />
      <parent
        link="link_5" />
      <child
        link="link_6" />
      <axis
        xyz="0 0 -1" />
      <limit
        lower="${radians(-350)}"
        upper="${radians(350)}"
        effort="100"
        velocity="1" />
    </joint>

		<link
		  name="tool0">
		  <inertial>
		    <origin
		      xyz="5.0734E-05 -0.032347 -0.061828"
		      rpy="0 0 0" />
		    <mass
		      value="0.01" />
		    <inertia
		      ixx="1.6923"
		      ixy="0.00014315"
		      ixz="-5.407E-06"
		      iyy="4.8227"
		      iyz="-0.0008361"
		      izz="6.5026" />
		  </inertial>
		  <visual>
		    <origin
		      xyz="0 0 0.29"
		      rpy="0 0 0" />
		    <geometry>
		      <mesh
		        filename="package://lt_description/meshes/kr210r2700_cover/tool.STL" />
		    </geometry>
		    <material
		      name="">
		      <color
		        rgba="0.75294 0.75294 0.75294 1" />
		    </material>
		  </visual>
		  <collision>
		    <origin
		      xyz="0 0 0.29"
		      rpy="0 0 0" />
		    <geometry>
		      <mesh
		        filename="package://lt_description/meshes/kr210r2700_cover/tool.STL" />
		    </geometry>
		  </collision>
		</link>
    <joint
      name="joint_a6_tool0"
      type="fixed">
      <origin
        xyz="0 0 0.33376"
        rpy="0 3.14159 1.5708" />
      <parent
        link="link_6" />
      <child
        link="tool0" />
    </joint>
  </xacro:macro>
</robot>
