<?xml version="1.0" ?>
<!-- =================================================================================== -->
<!-- |    This document was autogenerated by xacro from /home/nvidia/catkin_ws/src/leapting/bringup/urdf/test/kr2700.urdf.xacro | -->
<!-- |    EDITING THIS FILE BY HAND IS NOT RECOMMENDED                                 | -->
<!-- =================================================================================== -->
<robot name="kr2700">
    <link name="base_arm">
        <inertial>
            <origin rpy="0 0 0" xyz="-0.11721 0.00093362 0.10365" />
            <mass value="553.48" />
            <inertia ixx="12.503" ixy="0.066841" ixz="2.8363" iyy="27.301" iyz="-0.016485" izz="33.309" />
        </inertial>
        <visual>
            <origin rpy="0 0 0" xyz="0 0 0" />
            <geometry>
                <mesh filename="package://bringup/meshes/kr2700/base_arm.STL" />
            </geometry>
            <material name="">
                <color rgba="0.75294 0.75294 0.75294 1" />
            </material>
        </visual>
        <collision>
            <origin rpy="0 0 0" xyz="0 0 0" />
            <geometry>
                <mesh filename="package://bringup/meshes/kr2700/base_arm.STL" />
            </geometry>
        </collision>
    </link>
    <link name="link_1">
        <inertial>
            <origin rpy="0 0 0" xyz="-0.011212 0.01436 0.24467" />
            <mass value="633.8" />
            <inertia ixx="17.857" ixy="-2.6899" ixz="1.6654" iyy="33.002" iyz="-0.49207" izz="29.842" />
        </inertial>
        <visual>
            <origin rpy="0 0 0" xyz="0 0 0" />
            <geometry>
                <mesh filename="package://bringup/meshes/kr2700/link_1.STL" />
            </geometry>
            <material name="">
                <color rgba="0.75294 0.75294 0.75294 1" />
            </material>
        </visual>
        <collision>
            <origin rpy="0 0 0" xyz="0 0 0" />
            <geometry>
                <mesh filename="package://bringup/meshes/kr2700/link_1.STL" />
            </geometry>
        </collision>
    </link>
    <joint name="joint_a1" type="revolute">
        <origin rpy="0 0 0" xyz="0 0 0.2236" />
        <parent link="base_arm" />
        <child link="link_1" />
        <axis xyz="0 0 -1" />
        <limit effort="100" lower="-3.220132469929538" upper="3.141592653589793" velocity="1" />
    </joint>
    <link name="link_2">
        <inertial>
            <origin rpy="0 0 0" xyz="0.44927 0.00098297 -0.2316" />
            <mass value="691.94" />
            <inertia ixx="11.762" ixy="0.38402" ixz="9.1746" iyy="137.26" iyz="-0.011243" izz="135.8" />
        </inertial>
        <visual>
            <origin rpy="0 0 0" xyz="0 0 0" />
            <geometry>
                <mesh filename="package://bringup/meshes/kr2700/link_2.STL" />
            </geometry>
            <material name="">
                <color rgba="0.75294 0.75294 0.75294 1" />
            </material>
        </visual>
        <collision>
            <origin rpy="0 0 0" xyz="0 0 0" />
            <geometry>
                <mesh filename="package://bringup/meshes/kr2700/link_2.STL" />
            </geometry>
        </collision>
    </link>
    <joint name="joint_a2" type="revolute">
        <origin rpy="-1.5708 0 0" xyz="0.33 0.009 0.4094" />
        <parent link="link_1" />
        <child link="link_2" />
        <axis xyz="0 0 1" />
        <limit effort="100" lower="-2.443460952792061" upper="-0.08621926504851989" velocity="1" />
    </joint>
    <link name="link_3">
        <inertial>
            <origin rpy="0 0 0" xyz="0.26439 -0.10607 0.10511" />
            <mass value="462.1" />
            <inertia ixx="3.9646" ixy="0.046601" ixz="-0.78788" iyy="31.952" iyz="0.20533" izz="31.684" />
        </inertial>
        <visual>
            <origin rpy="0 0 0" xyz="0 0 0" />
            <geometry>
                <mesh filename="package://bringup/meshes/kr2700/link_3.STL" />
            </geometry>
            <material name="">
                <color rgba="0.75294 0.75294 0.75294 1" />
            </material>
        </visual>
        <collision>
            <origin rpy="0 0 0" xyz="0 0 0" />
            <geometry>
                <mesh filename="package://bringup/meshes/kr2700/link_3.STL" />
            </geometry>
        </collision>
    </link>
    <joint name="joint_a3" type="revolute">
        <origin rpy="0 0 -1.57079" xyz="1.15 0 -0.114" />
        <parent link="link_2" />
        <child link="link_3" />
        <axis xyz="0 0 1" />
        <limit effort="100" lower="-0.8377580409572782" upper="2.9321531433504737" velocity="1" />
    </joint>
    <link name="link_4">
        <inertial>
            <origin rpy="0 0 0" xyz="-5.2916E-06 -0.0044928 0.18467" />
            <mass value="39.417" />
            <inertia ixx="0.69268" ixy="7.2733E-06" ixz="-1.9285E-05" iyy="0.6955" iyz="0.031592" izz="0.097091" />
        </inertial>
        <visual>
            <origin rpy="0 0 0" xyz="0 0 0" />
            <geometry>
                <mesh filename="package://bringup/meshes/kr2700/link_4.STL" />
            </geometry>
            <material name="">
                <color rgba="0.75294 0.75294 0.75294 1" />
            </material>
        </visual>
        <collision>
            <origin rpy="0 0 0" xyz="0 0 0" />
            <geometry>
                <mesh filename="package://bringup/meshes/kr2700/link_4.STL" />
            </geometry>
        </collision>
    </link>
    <joint name="joint_a4" type="revolute">
        <origin rpy="-1.5708 0 0" xyz="0.115 0.8685 0.105" />
        <parent link="link_3" />
        <child link="link_4" />
        <axis xyz="0 0 -1" />
        <limit effort="100" lower="-3.141592653589793" upper="3.141592653589793" velocity="1" />
    </joint>
    <link name="link_5">
        <inertial>
            <origin rpy="0 0 0" xyz="-4.5381E-05 0.051765 -0.025172" />
            <mass value="53.275" />
            <inertia ixx="0.66981" ixy="0.00015038" ixz="0.00027093" iyy="0.4771" iyz="0.11692" izz="0.42151" />
        </inertial>
        <visual>
            <origin rpy="0 0 0" xyz="0 0 0" />
            <geometry>
                <mesh filename="package://bringup/meshes/kr2700/link_5.STL" />
            </geometry>
            <material name="">
                <color rgba="0.75294 0.75294 0.75294 1" />
            </material>
        </visual>
        <collision>
            <origin rpy="0 0 0" xyz="0 0 0" />
            <geometry>
                <mesh filename="package://bringup/meshes/kr2700/link_5.STL" />
            </geometry>
        </collision>
    </link>
    <joint name="joint_a5" type="revolute">
        <origin rpy="1.5708 0 0" xyz="0 -0.059 0.3515" />
        <parent link="link_4" />
        <child link="link_5" />
        <axis xyz="0 0 1" />
        <limit effort="100" lower="-1.5707963267948966" upper="1.9198621771937625" velocity="1" />
    </joint>
    <link name="link_6">
        <inertial>
            <origin rpy="0 0 0" xyz="2.1759E-05 -4.6365E-05 0.023222" />
            <mass value="4.4993" />
            <inertia ixx="0.0059812" ixy="4.6968E-06" ixz="-1.062E-06" iyy="0.0059674" iyz="1.7586E-06" izz="0.010749" />
        </inertial>
        <visual>
            <origin rpy="0 0 0" xyz="0 0 0" />
            <geometry>
                <mesh filename="package://bringup/meshes/kr2700/link_6.STL" />
            </geometry>
            <material name="">
                <color rgba="0.75294 0.75294 0.75294 1" />
            </material>
        </visual>
        <collision>
            <origin rpy="0 0 0" xyz="0 0 0" />
            <geometry>
                <mesh filename="package://bringup/meshes/kr2700/link_6.STL" />
            </geometry>
        </collision>
    </link>
    <joint name="joint_a6" type="revolute">
        <origin rpy="-1.5708 0 0" xyz="0 0.17 -0.059" />
        <parent link="link_5" />
        <child link="link_6" />
        <axis xyz="0 0 -1" />
        <limit effort="100" lower="-3.141592653589793" upper="3.141592653589793" velocity="1" />
    </joint>
    <link name="tool0">
        <inertial>
            <origin rpy="0 0 0" xyz="5.0734E-05 -0.032347 -0.061828" />
            <mass value="0.01" />
            <inertia ixx="1.6923" ixy="0.00014315" ixz="-5.407E-06" iyy="4.8227" iyz="-0.0008361" izz="6.5026" />
        </inertial>
        <visual>
            <origin rpy="0 0 0" xyz="0 0 0.29" />
            <geometry>
                <mesh filename="package://bringup/meshes/kr2700/tool.STL" />
            </geometry>
            <material name="">
                <color rgba="0.75294 0.75294 0.75294 1" />
            </material>
        </visual>
        <collision>
            <origin rpy="0 0 0" xyz="0 0 0.29" />
            <geometry>
                <mesh filename="package://bringup/meshes/kr2700/tool.STL" />
            </geometry>
        </collision>
    </link>
    <joint name="joint_a6_tool0" type="fixed">
        <origin rpy="0 3.14159 1.5708" xyz="0 0 0.33376" />
        <parent link="link_6" />
        <child link="tool0" />
    </joint>
    <transmission name="trans_joint_a1">
        <type>transmission_interface/SimpleTransmission</type>
        <joint name="joint_a1">
            <hardwareInterface>hardware_interface/EffortJointInterface</hardwareInterface>
        </joint>
        <actuator name="joint_a1_motor">
            <hardwareInterface>hardware_interface/EffortJointInterface</hardwareInterface>
            <mechanicalReduction>1</mechanicalReduction>
        </actuator>
    </transmission>
    <transmission name="trans_joint_a2">
        <type>transmission_interface/SimpleTransmission</type>
        <joint name="joint_a2">
            <hardwareInterface>hardware_interface/EffortJointInterface</hardwareInterface>
        </joint>
        <actuator name="joint_a2_motor">
            <hardwareInterface>hardware_interface/EffortJointInterface</hardwareInterface>
            <mechanicalReduction>1</mechanicalReduction>
        </actuator>
    </transmission>
    <transmission name="trans_joint_a3">
        <type>transmission_interface/SimpleTransmission</type>
        <joint name="joint_a3">
            <hardwareInterface>hardware_interface/EffortJointInterface</hardwareInterface>
        </joint>
        <actuator name="joint_a3_motor">
            <hardwareInterface>hardware_interface/EffortJointInterface</hardwareInterface>
            <mechanicalReduction>1</mechanicalReduction>
        </actuator>
    </transmission>
    <transmission name="trans_joint_a4">
        <type>transmission_interface/SimpleTransmission</type>
        <joint name="joint_a4">
            <hardwareInterface>hardware_interface/EffortJointInterface</hardwareInterface>
        </joint>
        <actuator name="joint_a4_motor">
            <hardwareInterface>hardware_interface/EffortJointInterface</hardwareInterface>
            <mechanicalReduction>1</mechanicalReduction>
        </actuator>
    </transmission>
    <transmission name="trans_joint_a5">
        <type>transmission_interface/SimpleTransmission</type>
        <joint name="joint_a5">
            <hardwareInterface>hardware_interface/EffortJointInterface</hardwareInterface>
        </joint>
        <actuator name="joint_a5_motor">
            <hardwareInterface>hardware_interface/EffortJointInterface</hardwareInterface>
            <mechanicalReduction>1</mechanicalReduction>
        </actuator>
    </transmission>
    <transmission name="trans_joint_a6">
        <type>transmission_interface/SimpleTransmission</type>
        <joint name="joint_a6">
            <hardwareInterface>hardware_interface/EffortJointInterface</hardwareInterface>
        </joint>
        <actuator name="joint_a6_motor">
            <hardwareInterface>hardware_interface/EffortJointInterface</hardwareInterface>
            <mechanicalReduction>1</mechanicalReduction>
        </actuator>
    </transmission>
    <gazebo>
        <plugin name="gazebo_ros_control">
            <robotNamespace>/</robotNamespace>
        </plugin>
    </gazebo>
</robot>

